2024-05-24 17:51:17,532 - INFO - Initializing CubicForwardSpline
2024-05-24 17:51:17,533 - INFO - Finished initializing CubicForwardSpline
2024-05-24 17:51:19,941 - INFO - Starting load_data
2024-05-24 17:51:19,956 - INFO - Finished load_data
2024-05-24 17:51:25,292 - INFO - Starting load_data
2024-05-24 17:51:25,299 - ERROR - Exception occurred in load_data
Traceback (most recent call last):
  File "/Users/arbili/opt/anaconda3/envs/whisperx/lib/python3.10/site-packages/pandas/core/indexes/base.py", line 3790, in get_loc
    return self._engine.get_loc(casted_key)
  File "index.pyx", line 152, in pandas._libs.index.IndexEngine.get_loc
  File "index.pyx", line 181, in pandas._libs.index.IndexEngine.get_loc
  File "pandas/_libs/hashtable_class_helper.pxi", line 7080, in pandas._libs.hashtable.PyObjectHashTable.get_item
  File "pandas/_libs/hashtable_class_helper.pxi", line 7088, in pandas._libs.hashtable.PyObjectHashTable.get_item
KeyError: 'tenor'

The above exception was the direct cause of the following exception:

Traceback (most recent call last):
  File "/Users/arbili/Arik/CubicForwardSpline/notebooks/../model/model.py", line 246, in load_data
    self.params['t1'] = self.params['tenor']
  File "/Users/arbili/opt/anaconda3/envs/whisperx/lib/python3.10/site-packages/pandas/core/frame.py", line 3893, in __getitem__
    indexer = self.columns.get_loc(key)
  File "/Users/arbili/opt/anaconda3/envs/whisperx/lib/python3.10/site-packages/pandas/core/indexes/base.py", line 3797, in get_loc
    raise KeyError(key) from err
KeyError: 'tenor'
